Workbook

Sheet Alur Data
A1: ALUR DATA SISTEM → OUTPUT DOKUMEN SURAT TUGAS, SPD, LAMPIRAN & VISUM
A2: Diperbarui sesuai demo terbaru E-Surat & SPD Online (Pusdiklat Kemlu) dan disesuaikan dengan 4 template output: Format ST, SPD (PMK 113/PMK.05/2012), Lampiran SPD, dan Visum Rampungan.
A3: Cara update: edit langsung teks di sel; Status Pengisian & Acuan berupa dropdown. Tambah baris baru di dalam tabel agar filter & ringkasan ikut terhitung. Pemetaan per field template ada di sheet 'Pemetaan Template'. Baris berlabel Acuan "Template (usulan)" belum ada di demo.
A4: No | B4: Tahap di Sistem | C4: Aktor | D4: Bagian Form | E4: Data yang Diinput User / Source | F4: Field pada Output Dokumen (ST / SPD / Lampiran / Visum) | G4: Metode Validasi / Logika Sistem | H4: Status Pengisian | I4: Acuan
A5: 1 | B5: 1. Upload Nota / Undangan | C5: Sespalu / Pihak Eksternal | D5: Kategori Perjalanan Dinas | E5: Kategori Perjalanan Dinas: Dalam Negeri (wilayah Indonesia) atau Luar Negeri / LN (perlu Izin Setneg & Paspor Dinas) | F5: [Dok 1 ST] "di (Tempat Kegiatan)" memuat Kota, Negara & No Izin Setneg jika LN [Dok 2 SPD] Poin 4 (tambahan "Luar Negeri: negara"), Poin 6b Tempat Tujuan [Dok 4 Visum] Ke / Tiba di / Berangkat dari (tujuan LN) Menampilkan field khusus LN (Negara Tujuan, Nomor Izin Setneg) di Tahap 3 dan upload Izin Setneg di Tahap 1 | G5: Radio button (default Dalam Negeri). Jika LN: label tujuan menjadi "Kota / Venue Tujuan LN", muncul field Negara Tujuan & Nomor Izin Setneg, default angkutan Perjalanan Udara; badge kategori di header berubah | H5: Input Manual | I5: Demo
A6: 1 | B6: 1. Upload Nota / Undangan | C6: Sespalu / Pihak Eksternal | D6: Data Nota / Undangan | E6: Sumber Nota/Undangan (Pihak Eksternal / Internal Sespalu-Kemlu), Nomor Nota/Undangan, Instansi/Unit Pengirim, Tanggal Undangan, Perihal Undangan/Kegiatan | F6: [Dok 1 ST] "Dalam rangka (Tujuan Kegiatan)" = perihal; "sesuai (Undangan/Nota Dinas) (Asal Surat) Nomor (Nomor) tanggal (Tanggal)" = jenis surat (Eksternal = Undangan, Internal = Nota Dinas), Instansi Pengirim, Nomor, Tanggal Undangan; "untuk menghadiri (Nama Kegiatan)" = perihal [Dok 2 SPD] Poin 4 (Maksud Perjalanan Dinas) [Dok 4 Visum] "Kepala [Instansi Tujuan]" pada blok Tiba di / Berangkat dari = Instansi/Unit Pengirim [Tahap 2] Ringkasan Nota untuk Kapus; [Tahap 4] Maksud Kegiatan untuk TU | G6: Field bertanda * wajib diisi (required). Tujuan Kegiatan dan Nama Kegiatan pada ST sama-sama diambil dari Perihal Undangan (belum ada isian terpisah). Tanggal tampil format ISO (2026-08-20) | H6: Input Manual | I6: Demo & Template
A7: 1 | B7: 1. Upload Nota / Undangan | C7: Sespalu / Pihak Eksternal | D7: Upload Berkas | E7: File PDF Scan Undangan (maks 10MB); File Izin Setneg / Keppres (khusus LN) | F7: Arsip berkas sumber penugasan (tidak dicetak pada dokumen output). Nomor Izin Setneg diinput di Tahap 3 | G7: Upload PDF maks 10MB; Izin Setneg/Keppres wajib untuk Dinas LN (ditandai *). Tombol "Kirim ke Kepala Pusat (Kapus)" melanjutkan ke Tahap 2 | H7: Input Manual | I7: Demo
A8: 2 | B8: 2. Disposisi Kapus | C8: Kapus (Kepala Pusat) | D8: Keputusan & Catatan Disposisi | E8: Keputusan Tindak Lanjut: Setuju/Ya (lanjut buat ST & SPD), Minta Revisi (kembalikan ke Sespalu), Hentikan/Stop (tidak ditindaklanjuti); Catatan Disposisi / Instruksi Penunjukan Tim | F8: Disposisi Kapus tersimpan sebagai dasar pengerjaan; tidak tercetak pada dokumen output. Kapus meninjau Ringkasan Nota/Undangan (Nomor, Pengirim, Perihal) sebelum memutuskan | G8: Radio button 3 pilihan (default Setuju/Ya); catatan disposisi berupa textarea (di demo bersifat opsional). Tombol "Proses Disposisi" melanjutkan ke Tahap 3 | H8: Approval / Action | I8: Demo
A9: 3 | B9: 3. Draft Rincian Tugas (Sespalu) | C9: Sespalu | D9: Identitas PPK & Pengiriman Draft | E9: Pilih Pejabat Pembuat Komitmen (PPK) dari dropdown (di demo: GEORGE JUNIOR atau PIPIN ZAENAL HAPINUDIN); Nama & NIP terisi otomatis. Nomor ST & SPD tidak diisi di tahap ini (diisi TU pada Tahap 4) | F9: [Dok 2 SPD] Poin 1 (Pejabat Pembuat Komitmen), Nama & NIP pada blok TTD [Dok 3 Lampiran] Blok Mengetahui/Menyetujui PPK (Nama & NIP) [Dok 4 Visum] Blok I dan Blok VI (Nama & NIP PPK), pada "Telah diperiksa..." | G9: Dropdown wajib dipilih (required); Nama dan NIP tersimpan bersama. Form memuat catatan penomoran oleh TU. Tombol "Kirim Draft ke Tata Usaha (TU)" melanjutkan ke Tahap 4 | H9: Auto-populated | I9: Demo & Template
A10: 3 | B10: 3. Draft Rincian Tugas (Sespalu) | C10: Sespalu | D10: Data Tetap Dokumen | E10: Tidak ada input: kop Kemlu, Kepala Pusat penandatangan ST (KHASAN ASHARI, NIP 19750617 200003 1 001), Tembusan ST, Lembar & Kode No SPD, kota dikeluarkan, Satuan Kerja & Kementerian pada Lampiran, teks baku | F10: [Dok 1 ST] Kop, paragraf baku, Dikeluarkan di Jakarta, TTD & NIP Kepala Pusat, Tembusan 1-3 (Administrator AMS/PMS, Yang bersangkutan, Arsip) [Dok 2 SPD] Rujukan PMK 113/PMK.05/2012, KEMENTERIAN LUAR NEGERI (PUSAT PENDIDIKAN DAN PELATIHAN), Lembar: 1, Kode No: DL-SPD/2026, Dikeluarkan di: Jakarta, "*) coret yang tidak perlu" [Dok 3 Lampiran] Rujukan Lampiran IV Peraturan Dirjen Perbendaharaan, Satuan Kerja, Kementerian Negara/Lembaga [Dok 4 Visum] Kop, "- 2 -", teks "Telah diperiksa...", Blok VIII Perhatian | G10: Data tetap di demo (belum dari master). Tanggal surat pada ST, SPD, dan Lampiran juga tetap (lihat baris Tanggal Surat Tugas & SPD di Tahap 4) | H10: System Generated | I10: Demo & Template
A11: 3 | B11: 3. Draft Rincian Tugas (Sespalu) | C11: Sespalu | D11: Personel yang Ditugaskan (Multi-Pegawai) | E11: Pilih Pegawai dari Master Data Pusdiklat Kemlu lalu "Tambah Pegawai" (bisa lebih dari satu); hapus pegawai dari daftar | F11: [Dok 1 ST] Tabel (No, Nama/NIP, Pangkat/Golongan, Jabatan) [Dok 2 SPD] Poin 2 (Nama & NIP pegawai pertama, ditambah "dkk" jika lebih dari 1), Poin 3a/3b (Pangkat/Golongan, Jabatan/Instansi; "Terlampir" jika lebih dari 1 pegawai) [Dok 3 Lampiran] Kolom Nama Pelaksana SPD / NIP / Jabatan / Pangkat Golongan [Tahap 4] Ringkasan Personel Ditugaskan ("Nama, dkk (N orang)") | G11: Minimal 1 pegawai; NIP yang sama tidak boleh ditambahkan dua kali. Pangkat & jabatan di-snapshot saat pegawai ditambahkan. Kolom Status Profil: "Sesuai Master" atau "Snapshot Terkunci" | H11: Auto-populated | I11: Demo & Template
A12: 3 | B12: 3. Draft Rincian Tugas (Sespalu) | C12: Sespalu | D12: Master Pegawai & Promosi (Snapshot Lock) | E12: Update Pangkat/Golongan & Jabatan pegawai di Master Data (simulasi kenaikan pangkat) | F12: Tidak mengubah ST/SPD yang sudah memakai snapshot; hanya mengubah dropdown Master dan penanda Status Profil pada draft | G12: Aturan Imutabilitas Snapshot: perubahan Master tidak mengubah profil pangkat/jabatan pada dokumen lama. Badge "Snapshot Terkunci" muncul jika Master berbeda dari snapshot | H12: Input Manual | I12: Demo
A13: 3 | B13: 3. Draft Rincian Tugas (Sespalu) | C13: Sespalu | D13: Tingkat Biaya & Angkutan | E13: Tingkat Biaya SPD (A / B / C), Alat Angkutan (Perjalanan Darat / Perjalanan Udara-Tiket / Kendaraan Dinas) | F13: [Dok 2 SPD] Poin 3c (Tingkat Biaya; "Terlampir" jika lebih dari 1 pegawai), Poin 5 (Alat angkutan yang dipergunakan) [Dok 3 Lampiran] Kolom Tingkat Biaya Perjalanan Dinas dan Alat Angkutan yang digunakan (baris pegawai berikutnya "idem") | G13: Dropdown pilihan tetap; Tingkat Biaya & Angkutan wajib (*) | H13: Input Manual | I13: Demo & Template
A14: 3 | B14: 3. Draft Rincian Tugas (Sespalu) | C14: Sespalu | D14: Lokasi & Tanggal Perjalanan | E14: Tempat Berangkat, Tempat/Kota Tujuan, Tanggal Berangkat, Tanggal Harus Kembali | F14: [Dok 1 ST] "di (Tempat Kegiatan)" dan "pada tanggal (Tanggal Kegiatan)" (Tgl Berangkat s.d Tgl Kembali) [Dok 2 SPD] Poin 6a/6b (Berangkat/Tujuan), Poin 7b/7c (Tgl Berangkat / Tgl harus kembali) [Dok 3 Lampiran] Tanggal Penyelenggaraan, Kota Tempat Penyelenggaraan, kolom Tempat Kedudukan Asal (baris berikutnya "idem"), Tanggal Berangkat & Kembali [Dok 4 Visum] Blok I (Berangkat dari tempat kedudukan / Ke / Pada tanggal), Blok II (Tiba di / Pada tanggal), blok kepulangan (Berangkat dari / Ke / Pada tanggal), Blok VI (Tiba di tempat kedudukan / Pada tanggal) [Tahap 4] Ringkasan Lokasi Tujuan | G14: Field wajib diisi (required); tanggal memakai date picker. Tanggal tampil format ISO (2026-08-27) di dokumen | H14: Input Manual | I14: Demo & Template
A15: 3 | B15: 3. Draft Rincian Tugas (Sespalu) | C15: Sespalu | D15: Durasi Perjalanan (Otomatis) | E15: Tidak diinput; dihitung dari Tanggal Berangkat & Tanggal Harus Kembali | F15: [Dok 2 SPD] Poin 7a ("N (terbilang) hari") [Dok 3 Lampiran] Kolom Lama dinas (hari), tiap baris pegawai [Tahap 4] Ringkasan Durasi Dinas ("N hari (tgl s.d tgl)") Teks kalkulasi durasi tampil langsung di form Tahap 3 | G15: Lama Hari = (Tgl Kembali - Tgl Berangkat) + 1; dihitung ulang tiap tanggal diubah dan hanya jika Tgl Kembali >= Tgl Berangkat. Terbilang di demo baru tersedia sampai sepuluh, di atas itu tampil angka | H15: System Generated | I15: Demo & Template
A16: 3 | B16: 3. Draft Rincian Tugas (Sespalu) | C16: Sespalu | D16: Khusus Luar Negeri | E16: Negara Tujuan (Luar Negeri), Nomor Surat Izin SETNEG (field tampil hanya jika kategori = Luar Negeri) | F16: [Dok 1 ST] "di (Tempat Kegiatan)" menjadi "Kota, Negara (Izin Setneg No: ...)" [Dok 2 SPD] Poin 4 ("Luar Negeri: negara"), Poin 6b (Kota + Negara + No Izin Setneg) [Dok 4 Visum] Ke / Tiba di / Berangkat dari (Kota + Negara + No Izin Setneg) [Tahap 4] Ringkasan Lokasi Tujuan | G16: Tampil & ditandai wajib (*) hanya untuk kategori Luar Negeri; tersembunyi untuk Dalam Negeri | H16: Input Manual | I16: Demo
... A24: 5 | B24: 5. Output & Monitoring TTD PPK | C24: PPK (Pejabat Pembuat Komitmen) | D24: TTD Digital PPK (Non-Blocking) | E24: Aksi PPK: "Sematkan TTD Digital PPK" atau "Batalkan TTD PPK" (disimulasikan pada demo) | F24: Stempel digital "VERIFIED & APPROVED - PPK KEMLU - DIGITAL STAMP" pada area dokumen; hilang jika TTD dibatalkan | G24: Proses persuratan (penomoran, cetak, penerbitan) tetap berjalan meskipun PPK belum menandatangani. Satu tombol berlaku untuk seluruh dokumen; pada template PPK menandatangani SPD, Lampiran, dan Visum, sedangkan ST oleh Kepala Pusat | H24: Approval / Action | I24: Demo & Template

Sheet Pemetaan Template
A1: PEMETAAN FIELD TEMPLATE OUTPUT → SUMBER DATA DI ALUR
A2: Setiap bagian pada 4 template (Format_ST, SPD, Lampiran, Draft_Rampungan/Visum) dipetakan ke tahap & field input di Alur Data, beserta kondisinya pada demo terbaru.
A3: Kondisi di Demo: Terhubung = terisi dari input · Data tetap = teks/angka baku di dokumen · Belum ada input = template butuh data tetapi belum ada isiannya · Berbeda dari template = hasil di demo tidak sama dengan template.
A4: No | B4: Dokumen | C4: Bagian / Field di Template | D4: Sumber Data di Alur (Tahap · Field) | E4: Diisi Oleh | F4: Kondisi di Demo | G4: Keterangan / Selisih
A5: 1 | B5: Surat Tugas (ST) | C5: Kop: logo & KEMENTERIAN LUAR NEGERI / REPUBLIK INDONESIA | D5: Data tetap | E5: Sistem (data tetap) | F5: Data tetap | G5: Logo di demo masih kotak teks "KEMLU" (placeholder), bukan logo resmi
A6: 2 | B6: Surat Tugas (ST) | C6: Nomor: (Nomor) | D6: Tahap 4 · Nomor Surat Tugas Resmi | E6: TU | F6: Terhubung
A7: 3 | B7: Surat Tugas (ST) | C7: Dalam rangka (Tujuan Kegiatan) | D7: Tahap 1 · Perihal Undangan / Kegiatan | E7: Sespalu / Pihak Eksternal | F7: Terhubung | G7: Nama Kegiatan (baris di bawah) diambil dari isian yang sama, sehingga kalimat bisa terbaca berulang. Belum ada isian Tujuan Kegiatan dan Nama Kegiatan terpisah
A8: 4 | B8: Surat Tugas (ST) | C8: sesuai (Undangan/Nota Dinas) | D8: Tahap 1 · Sumber Nota/Undangan (Eksternal = Undangan, Internal = Nota Dinas) | E8: Sespalu / Pihak Eksternal | F8: Terhubung
A9: 5 | B9: Surat Tugas (ST) | C9: (Asal Surat) | D9: Tahap 1 · Instansi / Unit Pengirim | E9: Sespalu / Pihak Eksternal | F9: Terhubung
A10: 6 | B10: Surat Tugas (ST) | C10: Nomor (Nomor Undangan/Nota Dinas) | D10: Tahap 1 · Nomor Nota / Undangan | E10: Sespalu / Pihak Eksternal | F10: Terhubung
A11: 7 | B11: Surat Tugas (ST) | C11: tanggal (Tanggal Undangan/Nota Dinas) | D11: Tahap 1 · Tanggal Undangan | E11: Sespalu / Pihak Eksternal | F11: Terhubung
A12: 8 | B12: Surat Tugas (ST) | C12: Tabel No | Nama/NIP | Pangkat/Golongan | Jabatan | D12: Tahap 3 · Personel yang Ditugaskan (snapshot) | E12: Sespalu | F12: Terhubung | G12: Satu baris per pegawai
A13: 9 | B13: Surat Tugas (ST) | C13: untuk menghadiri (Nama Kegiatan) | D13: Tahap 1 · Perihal Undangan / Kegiatan | E13: Sespalu / Pihak Eksternal | F13: Terhubung | G13: Lihat catatan pada Tujuan Kegiatan
A14: 10 | B14: Surat Tugas (ST) | C14: di (Tempat Kegiatan) | D14: Tahap 3 · Tempat/Kota Tujuan (LN: + Negara Tujuan & Nomor Izin Setneg) | E14: Sespalu | F14: Terhubung
A15: 11 | B15: Surat Tugas (ST) | C15: pada tanggal (Tanggal Kegiatan) | D15: Tahap 3 · Tanggal Berangkat s.d Tanggal Harus Kembali | E15: Sespalu | F15: Terhubung | G15: Memakai rentang tanggal perjalanan dinas; belum ada tanggal kegiatan tersendiri
A16: 12 | B16: Surat Tugas (ST) | C16: Pembebanan DIPA Pusat Pendidikan dan Pelatihan Tahun Anggaran (Tahun Anggaran) | D16: Tahap 3 · Pembebanan Anggaran | E16: Sistem (data tetap) | F16: Data tetap | G16: Tahun Anggaran tetap 2026
A17: 13 | B17: Surat Tugas (ST) | C17: Paragraf baku "Surat tugas ini disusun..." dan "Demikian Surat Tugas ini..." | D17: Data tetap | E17: Sistem (data tetap) | F17: Data tetap | G17: Sudah sesuai template
A18: 14 | B18: Surat Tugas (ST) | C18: Dikeluarkan di Jakarta | D18: Data tetap | E18: Sistem (data tetap) | F18: Data tetap | G18: Sudah sesuai template
A19: 15 | B19: Surat Tugas (ST) | C19: Pada tanggal (Tanggal ST) | D19: Usulan: Tahap 4 · Tanggal Surat Tugas & SPD | E19: TU | F19: Belum ada input | G19: Di demo tetap 21 Agustus 2026
A20: 16 | B20: Surat Tugas (ST) | C20: Kepala Pusat Pendidikan dan Pelatihan: KHASAN ASHARI, NIP 19750617 200003 1 001 | D20: Data tetap | E20: Sistem (data tetap) | F20: Data tetap | G20: Belum ada aksi TTD Kepala Pusat di alur; penandatangan ST pada template adalah Kepala Pusat
A21: 17 | B21: Surat Tugas (ST) | C21: Tembusan: 1. Administrator AMS/PMS, 2. Yang bersangkutan, 3. Arsip | D21: Data tetap | E21: Sistem (data tetap) | F21: Data tetap | G21: Sudah sesuai template
A22: 18 | B22: SPD Lembar 1 | C22: Rujukan LAMPIRAN I PMK 113/PMK.05/2012 (kanan atas) | D22: Data tetap | E22: Sistem (data tetap) | F22: Data tetap
A23: 19 | B23: SPD Lembar 1 | C23: KEMENTERIAN LUAR NEGERI (PUSAT PENDIDIKAN DAN PELATIHAN) + logo | D23: Data tetap | E23: Sistem (data tetap) | F23: Data tetap
A24: 20 | B24: SPD Lembar 1 | C24: Lembar: 1 | D24: Data tetap | E24: Sistem (data tetap) | F24: Data tetap
A25: 21 | B25: SPD Lembar 1 | C25: Kode | D25: Data tetap | E25: Sistem (data tetap) | F25: Berbeda dari template | G25: Template: "Kode : -"; demo: "Kode No: DL-SPD/2026"
A26: 22 | B26: SPD Lembar 1 | C26: Nomor | D26: Tahap 4 · Nomor SPD Resmi | E26: TU | F26: Terhubung
A27: 23 | B27: SPD Lembar 1 | C27: 1. Pejabat Pembuat Komitmen | D27: Tahap 3 · Pilih PPK (Nama) | E27: Sespalu | F27: Terhubung
A28: 24 | B28: SPD Lembar 1 | C28: 2. Nama/NIP Pegawai yang melaksanakan perjalanan dinas | D28: Tahap 3 · Personel (pegawai pertama; "dkk" jika lebih dari 1) | E28: Sespalu | F28: Berbeda dari template | G28: Template: baris kedua poin 2 berisi "Terlampir" jika lebih dari 1 pegawai; demo menampilkan NIP pegawai pertama
A29: 25 | B29: SPD Lembar 1 | C29: 3a Pangkat dan Golongan, 3b Jabatan/Instansi, 3c Tingkat Biaya | D29: Tahap 3 · Personel & Tingkat Biaya | E29: Sespalu | F29: Terhubung | G29: "Terlampir" jika lebih dari 1 pegawai (sesuai template); 1 pegawai menampilkan nilainya
A30: 26 | B30: SPD Lembar 1 | C30: 4. Maksud Perjalanan Dinas | D30: Tahap 1 · Perihal (LN: + negara) | E30: Sespalu / Pihak Eksternal | F30: Terhubung
A31: 27 | B31: SPD Lembar 1 | C31: 5. Alat angkutan yang dipergunakan | D31: Tahap 3 · Alat Angkutan | E31: Sespalu | F31: Terhubung
A32: 28 | B32: SPD Lembar 1 | C32: 6a Tempat berangkat, 6b Tempat tujuan | D32: Tahap 3 · Tempat Berangkat, Tempat/Kota Tujuan | E32: Sespalu | F32: Terhubung
A33: 29 | B33: SPD Lembar 1 | C33: 7a Lamanya Perjalanan Dinas | D33: Tahap 3 · Durasi otomatis | E33: Sistem (otomatis) | F33: Terhubung | G33: Format "N (terbilang) hari" sesuai template; terbilang di demo baru sampai sepuluh
A34: 30 | B34: SPD Lembar 1 | C34: 7b Tanggal Berangkat, 7c Tanggal harus kembali/tiba di tempat baru *) | D34: Tahap 3 · Tanggal Berangkat, Tanggal Harus Kembali | E34: Sespalu | F34: Terhubung
A35: 31 | B35: SPD Lembar 1 | C35: 8. Pengikut: Nama / Tanggal Lahir / Keterangan (5 baris) | D35: Tidak ada input | E35: - | F35: Belum ada input | G35: Demo mencetak tabel kosong (2 baris "-"); input pengikut tidak ada di Tahap 3. Template menyediakan 5 baris
A36: 32 | B36: SPD Lembar 1 | C36: 9a Instansi, 9b Akun (Pembebanan Anggaran) | D36: Tahap 3 · Pembebanan Anggaran | E36: Sistem (data tetap) | F36: Data tetap | G36: Contoh template: a. Pusdiklat Kementerian Luar Negeri, b. kosong; demo mengisi keduanya dengan data tetap
A37: 33 | B37: SPD Lembar 1 | C37: 10. Keterangan lain-lain: Surat Tugas No. ... tanggal ... | D37: Tahap 4 · Nomor Surat Tugas + Tanggal Surat Tugas (usulan) | E37: TU | F37: Belum ada input | G37: Nomor terhubung; tanggal Surat Tugas belum ada input, demo memakai Tanggal Berangkat
A38: 34 | B38: SPD Lembar 1 | C38: *) coret yang tidak perlu | D38: Data tetap | E38: Sistem (data tetap) | F38: Data tetap
A39: 35 | B39: SPD Lembar 1 | C39: Dikeluarkan di: Jakarta | D39: Data tetap | E39: Sistem (data tetap) | F39: Data tetap
A40: 36 | B40: SPD Lembar 1 | C40: Tanggal (dikeluarkan) | D40: Usulan: Tahap 4 · Tanggal Surat Tugas & SPD | E40: TU | F40: Belum ada input | G40: Di demo tetap "Mei 2026"
...

Sheet Ringkasan
A1: Ringkasan Alur Data Sistem
A3: Total Tahapan Sistem | B3: =MAX('Alur Data'!A5:A44) -> 5
A4: Total Baris Data | B4: =COUNTA('Alur Data'!B5:B44) -> 20
A5: Output Terintegrasi (dokumen) | B5: 4 | C5: ST, SPD Lembar 1, Lampiran SPD, Visum Rampungan (diisi manual)
A7: Status Pengisian | B7: Jumlah Baris
A8: Auto-populated | B8: =COUNTIF('Alur Data'!$H$5:$H$44,A8) -> 4
A9: Input Manual | B9: =COUNTIF('Alur Data'!$H$5:$H$44,A9) -> 9
A10: System Generated | B10: =COUNTIF('Alur Data'!$H$5:$H$44,A10) -> 4
A11: Approval / Action | B11: =COUNTIF('Alur Data'!$H$5:$H$44,A11) -> 3
A12: Total | B12: =SUM(B8:B11) -> 20
A14: Catatan: angka di atas terhitung otomatis dari sheet 'Alur Data'. Jumlah dokumen (B5) dan kolom Peran diisi manual.
A16: Aktor | B16: Jumlah Baris | C16: Peran dalam Alur
A17: Sespalu / Pihak Eksternal | B17: =COUNTIF('Alur Data'!$C$5:$C$44,A17) -> 3 | C17: Mengunggah nota/undangan (Tahap 1)
A18: Kapus (Kepala Pusat) | B18: =COUNTIF('Alur Data'!$C$5:$C$44,A18) -> 1 | C18: Memberi disposisi keputusan (Tahap 2)
A19: Sespalu | B19: =COUNTIF('Alur Data'!$C$5:$C$44,A19) -> 9 | C19: Menyusun rincian tugas, PPK, personel, lokasi & tanggal (Tahap 3), lalu mengirim draft ke TU
A20: TU (Tata Usaha) | B20: =COUNTIF('Alur Data'!$C$5:$C$44,A20) -> 5 | C20: Memberi penomoran resmi ST & SPD (Tahap 4), menerima output dan mencetaknya (Tahap 5)
A21: PPK (Pejabat Pembuat Komitmen) | B21: =COUNTIF('Alur Data'!$C$5:$C$44,A21) -> 2 | C21: Memantau surat dan menandatangani surat yang diperlukan; non-blocking, proses tetap berjalan tanpa TTD PPK (Tahap 5)
A22: Total | B22: =SUM(B17:B21) -> 20
A24: Kesesuaian Demo dengan Template Output
A25: Dokumen | B25: Terhubung | C25: Data tetap | D25: Belum ada input | E25: Berbeda dari template | F25: Total
A26: Surat Tugas (ST) | B26: =COUNTIFS('Pemetaan Template'!$B$5:$B$96,$A26,'Pemetaan Template'!$F$5:$F$96,B$25) -> 10 | C26: =COUNTIFS('Pemetaan Template'!$B$5:$B$96,$A26,'Pemetaan Template'!$F$5:$F$96,C$25) -> 6 | D26: =COUNTIFS('Pemetaan Template'!$B$5:$B$96,$A26,'Pemetaan Template'!$F$5:$F$96,D$25) -> 1 | E26: =COUNTIFS('Pemetaan Template'!$B$5:$B$96,$A26,'Pemetaan Template'!$F$5:$F$96,E$25) -> 0 | F26: =SUM(B26:E26) -> 17
A27: SPD Lembar 1 | B27: =COUNTIFS('Pemetaan Template'!$B$5:$B$96,$A27,'Pemetaan Template'!$F$5:$F$96,B$25) -> 9 | C27: =COUNTIFS('Pemetaan Template'!$B$5:$B$96,$A27,'Pemetaan Template'!$F$5:$F$96,C$25) -> 6 | D27: =COUNTIFS('Pemetaan Template'!$B$5:$B$96,$A27,'Pemetaan Template'!$F$5:$F$96,D$25) -> 3 | E27: =COUNTIFS('Pemetaan Template'!$B$5:$B$96,$A27,'Pemetaan Template'!$F$5:$F$96,E$25) -> 2 | F27: =SUM(B27:E27) -> 20
A28: Lampiran SPD | B28: =COUNTIFS('Pemetaan Template'!$B$5:$B$96,$A28,'Pemetaan Template'!$F$5:$F$96,B$25) -> 11 | C28: =COUNTIFS('Pemetaan Template'!$B$5:$B$96,$A28,'Pemetaan Template'!$F$5:$F$96,C$25) -> 1 | D28: =COUNTIFS('Pemetaan Template'!$B$5:$B$96,$A28,'Pemetaan Template'!$F$5:$F$96,D$25) -> 4 | E28: =COUNTIFS('Pemetaan Template'!$B$5:$B$96,$A28,'Pemetaan Template'!$F$5:$F$96,E$25) -> 3 | F28: =SUM(B28:E28) -> 19
A29: Visum Rampungan | B29: =COUNTIFS('Pemetaan Template'!$B$5:$B$96,$A29,'Pemetaan Template'!$F$5:$F$96,B$25) -> 8 | C29: =COUNTIFS('Pemetaan Template'!$B$5:$B$96,$A29,'Pemetaan Template'!$F$5:$F$96,C$25) -> 2 | D29: =COUNTIFS('Pemetaan Template'!$B$5:$B$96,$A29,'Pemetaan Template'!$F$5:$F$96,D$25) -> 2 | E29: =COUNTIFS('Pemetaan Template'!$B$5:$B$96,$A29,'Pemetaan Template'!$F$5:$F$96,E$25) -> 2 | F29: =SUM(B29:E29) -> 14
A30: Umum | B30: =COUNTIFS('Pemetaan Template'!$B$5:$B$96,$A30,'Pemetaan Template'!$F$5:$F$96,B$25) -> 0 | C30: =COUNTIFS('Pemetaan Template'!$B$5:$B$96,$A30,'Pemetaan Template'!$F$5:$F$96,C$25) -> 0 | D30: =COUNTIFS('Pemetaan Template'!$B$5:$B$96,$A30,'Pemetaan Template'!$F$5:$F$96,D$25) -> 0 | E30: =COUNTIFS('Pemetaan Template'!$B$5:$B$96,$A30,'Pemetaan Template'!$F$5:$F$96,E$25) -> 2 | F30: =SUM(B30:E30) -> 2
A31: Total | B31: =SUM(B26:B30) -> 38 | C31: =SUM(C26:C30) -> 15 | D31: =SUM(D26:D30) -> 10 | E31: =SUM(E26:E30) -> 9 | F31: =SUM(F26:F30) -> 72
A32: Catatan: dihitung otomatis dari sheet 'Pemetaan Template' (kolom Dokumen dan Kondisi di Demo).

Sheet Catatan Perubahan
A1: CATATAN PERUBAHAN
A2: Update 3 = demo terbaru + 4 template PDF · Update 2 = penomoran oleh TU & TTD PPK non-blocking · Update 1 = tabel alur 7 tahap awal ke demo 5 tahap.
A3: Jenis: Baru = ada di demo saja · Diubah = ada di keduanya tetapi berbeda · Dihapus = tidak ada lagi di demo · Perlu Konfirmasi = perbedaan yang sebaiknya dicek ke tim/pembuat demo.
A4: No | B4: Update | C4: Area | D4: Sebelumnya | E4: Sesudah | F4: Jenis
A5: 1 | B5: Update 3 | C5: Dokumen output | D5: Output ST, SPD, Lampiran, dan Visum berformat sederhana | E5: Output mengikuti 4 template resmi (Format_ST, SPD PMK 113/PMK.05/2012, Lampiran IV Perdirjen, Draft Rampungan/Visum); tab keempat bernama "Lembar Visum Rampungan". Pemetaan lengkap ada di sheet Pemetaan Template | F5: Diubah
A6: 2 | B6: Update 3 | C6: Pilihan PPK | D6: Nama PPK berupa kolom isian di Tahap 3; NIP PPK tetap | E6: Dropdown dua PPK (GEORGE JUNIOR, PIPIN ZAENAL HAPINUDIN); Nama dan NIP terisi otomatis dan dipakai di SPD, Lampiran, dan Visum | F6: Diubah
A7: 3 | B7: Update 3 | C7: Kalimat Surat Tugas | D7: Tiga paragraf: Dasar Penugasan, Maksud Tugas, Pembebanan Anggaran; klausul Setneg pada Dasar Penugasan jika LN | E7: Kalimat mengikuti template: "Dalam rangka (Tujuan Kegiatan), sesuai (Undangan/Nota Dinas) (Asal Surat) Nomor ... tanggal ..., ... untuk menghadiri (Nama Kegiatan) di (Tempat Kegiatan) pada tanggal ...". Data LN (negara & Izin Setneg) kini hanya muncul pada bagian "di (Tempat Kegiatan)" | F7: Diubah
A8: 4 | B8: Update 3 | C8: Tembusan Surat Tugas | D8: Tidak ada (dihapus pada Update 1) | E8: Tembusan 1-3 (Administrator AMS/PMS, Yang bersangkutan, Arsip) kembali ada di ST | F8: Baru
A9: 5 | B9: Update 3 | C9: Penandatangan Surat Tugas | D9: DR. MOHAMAD HERY SARIPUDIN (NIP 19680315 199403 1 001), tetap | E9: KHASAN ASHARI (NIP 19750617 200003 1 001), tetap; belum ada aksi TTD Kepala Pusat di alur | F9: Diubah
A10: 6 | B10: Update 3 | C10: Struktur SPD | D10: SPD 8 poin: Pembebanan Anggaran di Poin 8a/8b, tanpa Pengikut | E10: SPD 10 poin sesuai template: Poin 8 Pengikut, Poin 9 Pembebanan Anggaran (9a/9b), Poin 10 Keterangan lain-lain (nomor Surat Tugas); "Terlampir" untuk Pangkat/Jabatan/Tingkat Biaya jika pegawai lebih dari 1; durasi "N (terbilang) hari" | F10: Diubah
A11: 7 | B11: Update 3 | C11: Pengikut SPD | D11: Tidak ada input maupun cetakan (dihapus pada Update 1) | E11: Tabel Pengikut tercetak di SPD Poin 8 tetapi kosong dan belum punya input di Tahap 3 | F11: Perlu Konfirmasi
A12: 8 | B12: Update 3 | C12: Lampiran SPD | D12: Matriks 8 kolom (No, Nama/NIP/Jabatan, Asal, Tingkat, Angkutan, No Surat Tugas, Tgl Dinas, Durasi) | E12: Format Daftar Peserta Kegiatan: Tanggal & Kota Penyelenggaraan, Satuan Kerja, Kementerian; 10 kolom (termasuk Ket); footer Mengetahui/Menyetujui PPK; "idem" untuk Tingkat Biaya, Angkutan, dan No Surat Tugas pada baris berikutnya | F12: Diubah
A13: 9 | B13: Update 3 | C13: Lembar Visum | D13: Dua blok: Berangkat dari/Ke dan Tiba di, dengan cap & TTD pejabat | E13: Format rampungan blok I sampai VIII (Berangkat, Tiba di, persinggahan, Tiba di tempat kedudukan, "Telah diperiksa...", Catatan Lain-lain, Perhatian) dengan TTD PPK pada blok I dan VI | F13: Diubah
A14: 10 | B14: Update 3 | C14: Tanggal Surat Tugas & SPD | D14: Tetap 21 Agustus 2026 (ST, SPD, Lampiran) | E14: Masih tetap di demo (ST & Lampiran 21 Agustus 2026, SPD "Mei 2026"); SPD Poin 10 dan Lampiran memakai Tanggal Berangkat sebagai tanggal Surat Tugas. Diusulkan input Tanggal Surat Tugas oleh TU di Tahap 4 (baris baru di Alur Data, Acuan "Template (usulan)") | F14: Perlu Konfirmasi
A15: 11 | B15: Update 3 | C15: Rujukan peraturan Lampiran | D15: - | E15: Demo menulis PER-22/PB/2011, template menulis PER-22/PB/2013 | F15: Perlu Konfirmasi
A16: 12 | B16: Update 3 | C16: Kode SPD & Poin 2 | D16: - | E16: Demo: "Kode No: DL-SPD/2026" dan Poin 2 menampilkan NIP pegawai pertama; template: Kode "-" dan Poin 2 baris kedua "Terlampir" jika pegawai lebih dari 1 | F16: Perlu Konfirmasi
... A45: 41 | B45: Update 1 | C45: Catatan teknis demo | D45: - | E45: Tanggal berangkat/kembali pada SPD Poin 7b/7c dan tanggal pada Visum tercetak statis (27 Agustus 2026 / 01 September 2026), belum mengikuti input Tahap 3. Tanggal pada Lampiran tampil berformat 2026-08-27 | F45: Perlu Konfirmasi
